Workbook
Name A: #REF!
Name Slicer_Driver_Name: #N/A

Sheet Summary Site
A1: Row Labels | B1: Sum of Tonnage B
A2: Lk Tlou - Sasol Bosjesspruit | B2: 71.25
A3: (blank)
A4: Tlou -Kangala | B4: 106.36
A5: Lk Tlou - Site -1,2.,3,4& Matla Pad | B5: 293.13
A6: Grand Total | B6: 470.74

Sheet Summary Driver
A9: Row Labels | B9: Sum of Tonnage | C9: Count of Route
A10: (blank)
A11: (blank)
A12: (blank)
A13: (blank)
A14: (blank)
A15: 26/11/2025
A16: (blank)
A17: (blank)
A18: (blank)
A19: 27/11/2025
A20: (blank)
A21: (blank)
... A34: (blank)
A35: Dumusani Masilela | B35: 109.9 | C35: 3
A36: 01/01/2026 | B36: 35.56 | C36: 1
A37: Lk Tlou - Site -1,2.,3,4& Matla Pad | B37: 35.56 | C37: 1
A38: 2930649 | B38: 35.56 | C38: 1
A39: LG24GXGP - FL11 | B39: 35.56 | C39: 1
A40: 07/01/2026 | B40: 74.34 | C40: 2
A41: Lk Tlou - Site -1,2.,3,4& Matla Pad | B41: 74.34 | C41: 2
A42: 2930934 | B42: 36.6 | C42: 1
A43: LG24GXGP - FL11 | B43: 36.6 | C43: 1
A44: 2931399 | B44: 37.74 | C44: 1
A45: LG24GXGP - FL11 | B45: 37.74 | C45: 1
A46: Production Mthethwa | B46: 249.44 | C46: 7
A47: 07/01/2026 | B47: 107.21 | C47: 3
A48: Lk Tlou - Sasol Bosjesspruit | B48: 34.85 | C48: 1
A49: 2930421 | B49: 34.85 | C49: 1
A50: LC18KPGP - FL05 | B50: 34.85 | C50: 1
A51: Tlou -Kangala | B51: 35 | C51: 1
A52: 3353 | B52: 35 | C52: 1
A53: LC18KPGP - FL05 | B53: 35 | C53: 1
A54: Lk Tlou - Site -1,2.,3,4& Matla Pad | B54: 37.36 | C54: 1
A55: 2930941 | B55: 37.36 | C55: 1
A56: LC18KPGP - FL05 | B56: 37.36 | C56: 1
A57: 08/01/2026 | B57: 35.94 | C57: 1
A58: Lk Tlou - Site -1,2.,3,4& Matla Pad | B58: 35.94 | C58: 1
A59: 2931387 | B59: 35.94 | C59: 1
A60: LC18KPGP - FL05 | B60: 35.94 | C60: 1
...

Sheet Combined
A1: Month | B1: Route | C1: Distance (KM) | D1: Rate (R) | E1: Date (DD/MM/YYY) | F1: Company | G1: Vehicle Reg # | H1: Driver Name | I1: Ticket A | J1: Tonnage A | K1: Ticket B | L1: Tonnage B | M1: Total Amount (R) | N1: Vat (15%) | O1: Total Incl Vat (R)
A2: Jan | B2: Lk Tlou - Site -1,2.,3,4& Matla Pad | C2: =VLOOKUP(B2,Data!$A$2:$C100,2,) -> 75 | D2: =VLOOKUP(B2,Data!$A$2:$C$100,3,) -> 122.14 | E2: 01/01/2026 | F2: Fleet Logix | G2: LG24GXGP - FL11 | H2: Dumusani Masilela | I2: 34888 | J2: 35.6 | K2: 2930649 | L2: 35.56 | M2: =L2*D2 -> 4343.2984 | N2: =M2*15% -> 651.49476 | O2: =SUM(M2:N2) -> 4994.7932 | AH2: =TEXT(E2,"dd/mm/yyyy") -> 01/01/2026
A3: Jan | B3: Lk Tlou - Site -1,2.,3,4& Matla Pad | C3: =VLOOKUP(B3,Data!$A$2:$B$100,2,) -> 75 | D3: =VLOOKUP(B3,Data!$A$2:$C$100,3,) -> 122.14 | E3: 07/01/2026 | F3: Fleet Logix | G3: LG24GXGP - FL11 | H3: Dumusani Masilela | I3: 34943 | J3: 36.66 | K3: 2930934 | L3: 36.6 | M3: =L3*D3 -> 4470.324 | N3: =M3*15% -> 670.5486 | O3: =SUM(M3:N3) -> 5140.8726 | AH3: =TEXT(E3,"dd/mm/yyyy") -> 07/01/2026
A4: Jan | B4: Lk Tlou - Site -1,2.,3,4& Matla Pad | C4: =VLOOKUP(B4,Data!$A$2:$C102,2,) -> 75 | D4: =VLOOKUP(B4,Data!$A$2:$C$100,3,) -> 122.14 | E4: 07/01/2026 | F4: Fleet Logix | G4: LG24GXGP - FL11 | H4: Dumusani Masilela | I4: 35025 | J4: 37.7 | K4: 2931399 | L4: 37.74 | M4: =L4*D4 -> 4609.5636 | N4: =M4*15% -> 691.43454 | O4: =SUM(M4:N4) -> 5300.9981 | AH4: =TEXT(E4,"dd/mm/yyyy") -> 07/01/2026
A5: Jan | B5: Lk Tlou - Site -1,2.,3,4& Matla Pad | C5: =VLOOKUP(B5,Data!$A$2:$B$100,2,) -> 75 | D5: =VLOOKUP(B5,Data!$A$2:$C$100,3,) -> 122.14 | E5: 08/01/2026 | F5: Fleet Logix | G5: LC18KPGP - FL05 | H5: Production Mthethwa | I5: 35021 | J5: 35.82 | K5: 2931387 | L5: 35.94 | M5: =L5*D5 -> 4389.7116 | N5: =M5*15% -> 658.45674 | O5: =SUM(M5:N5) -> 5048.1683 | AH5: =TEXT(E5,"dd/mm/yyyy") -> 08/01/2026
A6: Jan | B6: Lk Tlou - Site -1,2.,3,4& Matla Pad | C6: =VLOOKUP(B6,Data!$A$2:$C104,2,) -> 75 | D6: =VLOOKUP(B6,Data!$A$2:$C$100,3,) -> 122.14 | E6: 07/01/2026 | F6: Fleet Logix | G6: LC18KPGP - FL05 | H6: Production Mthethwa | I6: 34945 | J6: 37.22 | K6: 2930941 | L6: 37.36 | M6: =L6*D6 -> 4563.1504 | N6: =M6*15% -> 684.47256 | O6: =SUM(M6:N6) -> 5247.623 | AH6: =TEXT(E6,"dd/mm/yyyy") -> 07/01/2026
A7: Jan | B7: Lk Tlou - Sasol Bosjesspruit | C7: =VLOOKUP(B7,Data!$A$2:$B$100,2,) -> 85 | D7: =VLOOKUP(B7,Data!$A$2:$C$100,3,) -> 126.79 | E7: 07/01/2026 | F7: Fleet Logix | G7: LC18KPGP - FL05 | H7: Production Mthethwa | I7: 34854 | J7: 34.64 | K7: 2930421 | L7: 34.85 | M7: =L7*D7 -> 4418.6315 | N7: =M7*15% -> 662.79473 | O7: =SUM(M7:N7) -> 5081.4262 | AH7: =TEXT(E7,"dd/mm/yyyy") -> 07/01/2026
A8: Jan | B8: Tlou -Kangala | C8: =VLOOKUP(B8,Data!$A$2:$C106,2,) -> 23 | D8: =VLOOKUP(B8,Data!$A$2:$C$100,3,) -> 52 | E8: 07/01/2026 | F8: Fleet Logix | G8: LC18KPGP - FL05 | H8: Production Mthethwa | I8: 34917 | J8: 34.96 | K8: 3353 | L8: 35 | M8: =L8*D8 -> 1820 | N8: =M8*15% -> 273 | O8: =SUM(M8:N8) -> 2093 | AH8: =TEXT(E8,"dd/mm/yyyy") -> 07/01/2026
A9: Jan | B9: Lk Tlou - Sasol Bosjesspruit | C9: =VLOOKUP(B9,Data!$A$2:$B$100,2,) -> 85 | D9: =VLOOKUP(B9,Data!$A$2:$C$100,3,) -> 126.79 | E9: 06/01/2026 | F9: Fleet Logix | G9: LC18KPGP - FL05 | H9: Production Mthethwa | I9: 34774 | J9: 35.7 | K9: 2930151 | L9: 36.4 | M9: =L9*D9 -> 4615.156 | N9: =M9*15% -> 692.2734 | O9: =SUM(M9:N9) -> 5307.4294 | AH9: =TEXT(E9,"dd/mm/yyyy") -> 06/01/2026
A10: Jan | B10: Tlou -Kangala | C10: =VLOOKUP(B10,Data!$A$2:$C108,2,) -> 23 | D10: =VLOOKUP(B10,Data!$A$2:$C$100,3,) -> 52 | E10: 06/01/2026 | F10: Fleet Logix | G10: LC18KPGP - FL05 | H10: Production Mthethwa | I10: 34742 | J10: 34.74 | K10: 3293 | L10: 34.74 | M10: =L10*D10 -> 1806.48 | N10: =M10*15% -> 270.972 | O10: =SUM(M10:N10) -> 2077.452 | AH10: =TEXT(E10,"dd/mm/yyyy") -> 06/01/2026
A11: Jan | B11: Lk Tlou - Site -1,2.,3,4& Matla Pad | C11: =VLOOKUP(B11,Data!$A$2:$B$100,2,) -> 75 | D11: =VLOOKUP(B11,Data!$A$2:$C$100,3,) -> 122.14 | E11: 06/01/2026 | F11: Fleet Logix | G11: LC18KPGP - FL05 | H11: Production Mthethwa | I11: 34704 | J11: 35 | K11: 292638 | L11: 35.15 | M11: =L11*D11 -> 4293.221 | N11: =M11*15% -> 643.98315 | O11: =SUM(M11:N11) -> 4937.2041 | AH11: =TEXT(E11,"dd/mm/yyyy") -> 06/01/2026
A12: Jan | B12: Lk Tlou - Site -1,2.,3,4& Matla Pad | C12: =VLOOKUP(B12,Data!$A$2:$C110,2,) -> 75 | D12: =VLOOKUP(B12,Data!$A$2:$C$100,3,) -> 122.14 | E12: 07/01/2026 | F12: Fleet Logix | G12: KX32CBGP-FL33 | H12: Mbongiseni Mphikeleli Sithole | I12: 34937 | J12: 37.6 | K12: 290899 | L12: 37.86 | M12: =L12*D12 -> 4624.2204 | N12: =M12*15% -> 693.63306 | O12: =SUM(M12:N12) -> 5317.8535 | AH12: =TEXT(E12,"dd/mm/yyyy") -> 07/01/2026
A13: Jan | B13: Tlou -Kangala | C13: =VLOOKUP(B13,Data!$A$2:$B$100,2,) -> 23 | D13: =VLOOKUP(B13,Data!$A$2:$C$100,3,) -> 52 | E13: 06/01/2026 | F13: Fleet Logix | G13: KX32CBGP-FL33 | H13: Mbongiseni Mphikeleli Sithole | I13: 34744 | J13: 36.5 | K13: 3296 | L13: 36.62 | M13: =L13*D13 -> 1904.24 | N13: =M13*15% -> 285.636 | O13: =SUM(M13:N13) -> 2189.876 | AH13: =TEXT(E13,"dd/mm/yyyy") -> 06/01/2026
A14: Jan | B14: Lk Tlou - Site -1,2.,3,4& Matla Pad | C14: =VLOOKUP(B14,Data!$A$2:$C112,2,) -> 75 | D14: =VLOOKUP(B14,Data!$A$2:$C$100,3,) -> 122.14 | E14: 06/01/2026 | F14: Fleet Logix | G14: KX32CBGP-FL33 | H14: Mbongiseni Mphikeleli Sithole | I14: 34705 | J14: 36.72 | K14: 2929654 | L14: 36.92 | M14: =L14*D14 -> 4509.4088 | N14: =M14*15% -> 676.41132 | O14: =SUM(M14:N14) -> 5185.8201 | AH14: =TEXT(E14,"dd/mm/yyyy") -> 06/01/2026
A15: Jan | B15: Lk Tlou - Site -1,2.,3,4& Matla Pad | C15: =VLOOKUP(B15,Data!$A$2:$B$100,2,) -> 75 | D15: =VLOOKUP(B15,Data!$A$2:$C$100,3,) -> 122.14 | E15: 05/01/2026 | F15: Fleet Logix | G15: KX32CBGP-FL33 | H15: Mbongiseni Mphikeleli Sithole | I15: 34634 | J15: 37.7 | K15: 2929435 | L15: 38.06 | M15: =L15*D15 -> 4648.6484 | N15: =M15*15% -> 697.29726 | O15: =SUM(M15:N15) -> 5345.9457 | AH15: =TEXT(E15,"dd/mm/yyyy") -> 05/01/2026
A16: Jan | B16: Lk Tlou - Sasol Bosjesspruit | C16: =VLOOKUP(B16,Data!$A$2:$C114,2,) -> 85 | D16: =VLOOKUP(B16,Data!$A$2:$C$100,3,) -> 126.79 | E16: 06/01/2026 | F16: Fleet Logix | G16: KX32CBGP-FL33 | H16: Mbongiseni Mphikeleli Sithole | I16: 34777 | J16: 35.56 | K16: 2930138 | L16: 35.85 | M16: =L16*D16 -> 4545.4215 | N16: =M16*15% -> 681.81322 | O16: =SUM(M16:N16) -> 5227.2347 | AH16: =TEXT(E16,"dd/mm/yyyy") -> 06/01/2026
A17: Jan | C17: =VLOOKUP(B17,Data!$A$2:$B$100,2,) -> #N/A | D17: =VLOOKUP(B17,Data!$A$2:$C$100,3,) -> #N/A | F17: Fleet Logix | M17: =L17*D17 -> #N/A | N17: =M17*15% -> #N/A | O17: =SUM(M17:N17) -> #N/A | AH17: =TEXT(E17,"dd/mm/yyyy") -> 00/01/1900
A18: Jan | C18: =VLOOKUP(B18,Data!$A$2:$C116,2,) -> #N/A | D18: =VLOOKUP(B18,Data!$A$2:$C$100,3,) -> #N/A | F18: Fleet Logix | M18: =L18*D18 -> #N/A | N18: =M18*15% -> #N/A | O18: =SUM(M18:N18) -> #N/A | AH18: =TEXT(E18,"dd/mm/yyyy") -> 00/01/1900
A19: Jan | C19: =VLOOKUP(B19,Data!$A$2:$B$100,2,) -> #N/A | D19: =VLOOKUP(B19,Data!$A$2:$C$100,3,) -> #N/A | F19: Fleet Logix | M19: =L19*D19 -> #N/A | N19: =M19*15% -> #N/A | O19: =SUM(M19:N19) -> #N/A | AH19: =TEXT(E19,"dd/mm/yyyy") -> 00/01/1900
A20: Jan | C20: =VLOOKUP(B20,Data!$A$2:$C118,2,) -> #N/A | D20: =VLOOKUP(B20,Data!$A$2:$C$100,3,) -> #N/A | F20: Fleet Logix | M20: =L20*D20 -> #N/A | N20: =M20*15% -> #N/A | O20: =SUM(M20:N20) -> #N/A | AH20: =TEXT(E20,"dd/mm/yyyy") -> 00/01/1900
A21: Jan | C21: =VLOOKUP(B21,Data!$A$2:$B$100,2,) -> #N/A | D21: =VLOOKUP(B21,Data!$A$2:$C$100,3,) -> #N/A | F21: Fleet Logix | M21: =L21*D21 -> #N/A | N21: =M21*15% -> #N/A | O21: =SUM(M21:N21) -> #N/A | AH21: =TEXT(E21,"dd/mm/yyyy") -> 00/01/1900
A22: Jan | C22: =VLOOKUP(B22,Data!$A$2:$C120,2,) -> #N/A | D22: =VLOOKUP(B22,Data!$A$2:$C$100,3,) -> #N/A | F22: Fleet Logix | M22: =L22*D22 -> #N/A | N22: =M22*15% -> #N/A | O22: =SUM(M22:N22) -> #N/A | AH22: =TEXT(E22,"dd/mm/yyyy") -> 00/01/1900
A23: Jan | C23: =VLOOKUP(B23,Data!$A$2:$B$100,2,) -> #N/A | D23: =VLOOKUP(B23,Data!$A$2:$C$100,3,) -> #N/A | F23: Fleet Logix | M23: =L23*D23 -> #N/A | N23: =M23*15% -> #N/A | O23: =SUM(M23:N23) -> #N/A | AH23: =TEXT(E23,"dd/mm/yyyy") -> 00/01/1900
A24: Jan | C24: =VLOOKUP(B24,Data!$A$2:$C122,2,) -> #N/A | D24: =VLOOKUP(B24,Data!$A$2:$C$100,3,) -> #N/A | F24: Fleet Logix | M24: =L24*D24 -> #N/A | N24: =M24*15% -> #N/A | O24: =SUM(M24:N24) -> #N/A | AH24: =TEXT(E24,"dd/mm/yyyy") -> 00/01/1900
A25: Jan | C25: =VLOOKUP(B25,Data!$A$2:$B$100,2,) -> #N/A | D25: =VLOOKUP(B25,Data!$A$2:$C$100,3,) -> #N/A | F25: Fleet Logix | M25: =L25*D25 -> #N/A | N25: =M25*15% -> #N/A | O25: =SUM(M25:N25) -> #N/A | AH25: =TEXT(E25,"dd/mm/yyyy") -> 00/01/1900
A26: Jan | C26: =VLOOKUP(B26,Data!$A$2:$C124,2,) -> #N/A | D26: =VLOOKUP(B26,Data!$A$2:$C$100,3,) -> #N/A | F26: Fleet Logix | M26: =L26*D26 -> #N/A | N26: =M26*15% -> #N/A | O26: =SUM(M26:N26) -> #N/A | AH26: =TEXT(E26,"dd/mm/yyyy") -> 00/01/1900
A27: Jan | C27: =VLOOKUP(B27,Data!$A$2:$B$100,2,) -> #N/A | D27: =VLOOKUP(B27,Data!$A$2:$C$100,3,) -> #N/A | F27: Fleet Logix | M27: =L27*D27 -> #N/A | N27: =M27*15% -> #N/A | O27: =SUM(M27:N27) -> #N/A | AH27: =TEXT(E27,"dd/mm/yyyy") -> 00/01/1900
A28: Jan | C28: =VLOOKUP(B28,Data!$A$2:$C126,2,) -> #N/A | D28: =VLOOKUP(B28,Data!$A$2:$C$100,3,) -> #N/A | F28: Fleet Logix | M28: =L28*D28 -> #N/A | N28: =M28*15% -> #N/A | O28: =SUM(M28:N28) -> #N/A | AH28: =TEXT(E28,"dd/mm/yyyy") -> 00/01/1900
A29: Jan | C29: =VLOOKUP(B29,Data!$A$2:$B$100,2,) -> #N/A | D29: =VLOOKUP(B29,Data!$A$2:$C$100,3,) -> #N/A | F29: Fleet Logix | M29: =L29*D29 -> #N/A | N29: =M29*15% -> #N/A | O29: =SUM(M29:N29) -> #N/A | AH29: =TEXT(E29,"dd/mm/yyyy") -> 00/01/1900
A30: Jan | C30: =VLOOKUP(B30,Data!$A$2:$C128,2,) -> #N/A | D30: =VLOOKUP(B30,Data!$A$2:$C$100,3,) -> #N/A | F30: Fleet Logix | M30: =L30*D30 -> #N/A | N30: =M30*15% -> #N/A | O30: =SUM(M30:N30) -> #N/A | AH30: =TEXT(E30,"dd/mm/yyyy") -> 00/01/1900
A31: Jan | C31: =VLOOKUP(B31,Data!$A$2:$B$100,2,) -> #N/A | D31: =VLOOKUP(B31,Data!$A$2:$C$100,3,) -> #N/A | F31: Fleet Logix | M31: =L31*D31 -> #N/A | N31: =M31*15% -> #N/A | O31: =SUM(M31:N31) -> #N/A | AH31: =TEXT(E31,"dd/mm/yyyy") -> 00/01/1900
A32: Jan | C32: =VLOOKUP(B32,Data!$A$2:$C130,2,) -> #N/A | D32: =VLOOKUP(B32,Data!$A$2:$C$100,3,) -> #N/A | F32: Fleet Logix | M32: =L32*D32 -> #N/A | N32: =M32*15% -> #N/A | O32: =SUM(M32:N32) -> #N/A | AH32: =TEXT(E32,"dd/mm/yyyy") -> 00/01/1900
A33: Jan | C33: =VLOOKUP(B33,Data!$A$2:$B$100,2,) -> #N/A | D33: =VLOOKUP(B33,Data!$A$2:$C$100,3,) -> #N/A | F33: Fleet Logix | M33: =L33*D33 -> #N/A | N33: =M33*15% -> #N/A | O33: =SUM(M33:N33) -> #N/A | AH33: =TEXT(E33,"dd/mm/yyyy") -> 00/01/1900
A34: Jan | C34: =VLOOKUP(B34,Data!$A$2:$C132,2,) -> #N/A | D34: =VLOOKUP(B34,Data!$A$2:$C$100,3,) -> #N/A | F34: Fleet Logix | M34: =L34*D34 -> #N/A | N34: =M34*15% -> #N/A | O34: =SUM(M34:N34) -> #N/A | AH34: =TEXT(E34,"dd/mm/yyyy") -> 00/01/1900
A35: Jan | C35: =VLOOKUP(B35,Data!$A$2:$B$100,2,) -> #N/A | D35: =VLOOKUP(B35,Data!$A$2:$C$100,3,) -> #N/A | F35: Fleet Logix | M35: =L35*D35 -> #N/A | N35: =M35*15% -> #N/A | O35: =SUM(M35:N35) -> #N/A | AH35: =TEXT(E35,"dd/mm/yyyy") -> 00/01/1900
A36: Jan | C36: =VLOOKUP(B36,Data!$A$2:$C134,2,) -> #N/A | D36: =VLOOKUP(B36,Data!$A$2:$C$100,3,) -> #N/A | F36: Fleet Logix | M36: =L36*D36 -> #N/A | N36: =M36*15% -> #N/A | O36: =SUM(M36:N36) -> #N/A | AH36: =TEXT(E36,"dd/mm/yyyy") -> 00/01/1900
A37: Jan | C37: =VLOOKUP(B37,Data!$A$2:$B$100,2,) -> #N/A | D37: =VLOOKUP(B37,Data!$A$2:$C$100,3,) -> #N/A | F37: Fleet Logix | M37: =L37*D37 -> #N/A | N37: =M37*15% -> #N/A | O37: =SUM(M37:N37) -> #N/A | AH37: =TEXT(E37,"dd/mm/yyyy") -> 00/01/1900
A38: Jan | C38: =VLOOKUP(B38,Data!$A$2:$C136,2,) -> #N/A | D38: =VLOOKUP(B38,Data!$A$2:$C$100,3,) -> #N/A | F38: Fleet Logix | M38: =L38*D38 -> #N/A | N38: =M38*15% -> #N/A | O38: =SUM(M38:N38) -> #N/A | AH38: =TEXT(E38,"dd/mm/yyyy") -> 00/01/1900
A39: Jan | C39: =VLOOKUP(B39,Data!$A$2:$B$100,2,) -> #N/A | D39: =VLOOKUP(B39,Data!$A$2:$C$100,3,) -> #N/A | F39: Fleet Logix | M39: =L39*D39 -> #N/A | N39: =M39*15% -> #N/A | O39: =SUM(M39:N39) -> #N/A | AH39: =TEXT(E39,"dd/mm/yyyy") -> 00/01/1900
A40: Jan | C40: =VLOOKUP(B40,Data!$A$2:$C138,2,) -> #N/A | D40: =VLOOKUP(B40,Data!$A$2:$C$100,3,) -> #N/A | F40: Fleet Logix | M40: =L40*D40 -> #N/A | N40: =M40*15% -> #N/A | O40: =SUM(M40:N40) -> #N/A | AH40: =TEXT(E40,"dd/mm/yyyy") -> 00/01/1900
...

Sheet Daily Income Per Truck
B1: 01/01/2026 | C1: 02/01/2026 | D1: 03/01/2026 | E1: 04/01/2026 | F1: 05/01/2026 | G1: 06/01/2026 | H1: 07/01/2026 | I1: 08/01/2026 | J1: 09/01/2026 | K1: 10/01/2026 | L1: 11/01/2026 | M1: 12/01/2026 | N1: 13/01/2026 | O1: 14/01/2026 | P1: 15/01/2026 | Q1: 16/01/2026 | R1: 17/01/2026 | S1: 18/01/2026 | T1: 19/01/2026 | U1: 20/01/2026 | V1: 21/01/2026 | W1: 22/01/2026 | X1: 23/01/2026 | Y1: 24/01/2026 | Z1: 25/01/2026 | AA1: 26/01/2026 | AB1: 27/01/2026 | AC1: 28/01/2026 | AD1: 29/01/2026 | AE1: 30/01/2026 | AF1: 31/01/2026 | AG1: Total | AI1: 45992 | AJ1: =AI1+1 -> 45993 | AK1: =AJ1+1 -> 45994
A2: =Data!F2 -> KX31ZJGP - FL13 | B2: =SUMIFS(Combined!$O:$O,Combined!$G:$G,'Daily Income Per Truck'!$A2,Combined!$AH:$AH,'Daily Income Per Truck'!B$1) -> 0 | C2: =SUMIFS(Combined!$O:$O,Combined!$G:$G,'Daily Income Per Truck'!$A2,Combined!$AH:$AH,'Daily Income Per Truck'!C$1) -> 0 | D2: =SUMIFS(Combined!$O:$O,Combined!$G:$G,'Daily Income Per Truck'!$A2,Combined!$AH:$AH,'Daily Income Per Truck'!D$1) -> 0 | E2: =SUMIFS(Combined!$O:$O,Combined!$G:$G,'Daily Income Per Truck'!$A2,Combined!$AH:$AH,'Daily Income Per Truck'!E$1) -> 0 | F2: =SUMIFS(Combined!$O:$O,Combined!$G:$G,'Daily Income Per Truck'!$A2,Combined!$AH:$AH,'Daily Income Per Truck'!F$1) -> 0 | G2: =SUMIFS(Combined!$O:$O,Combined!$G:$G,'Daily Income Per Truck'!$A2,Combined!$AH:$AH,'Daily Income Per Truck'!G$1) -> 0 | H2: =SUMIFS(Combined!$O:$O,Combined!$G:$G,'Daily Income Per Truck'!$A2,Combined!$AH:$AH,'Daily Income Per Truck'!H$1) -> 0 | I2: =SUMIFS(Combined!$O:$O,Combined!$G:$G,'Daily Income Per Truck'!$A2,Combined!$AH:$AH,'Daily Income Per Truck'!I$1) -> 0 | ... AF2: =SUMIFS(Combined!$O:$O,Combined!$G:$G,'Daily Income Per Truck'!$A2,Combined!$AH:$AH,'Daily Income Per Truck'!AF$1) -> 0 | AG2: =SUM(B2:AF2) -> 0
A3: =Data!F3 -> KX31ZLGP - FL04 | B3: =SUMIFS(Combined!$O:$O,Combined!$G:$G,'Daily Income Per Truck'!$A3,Combined!$AH:$AH,'Daily Income Per Truck'!B$1) -> 0 | C3: =SUMIFS(Combined!$O:$O,Combined!$G:$G,'Daily Income Per Truck'!$A3,Combined!$AH:$AH,'Daily Income Per Truck'!C$1) -> 0 | D3: =SUMIFS(Combined!$O:$O,Combined!$G:$G,'Daily Income Per Truck'!$A3,Combined!$AH:$AH,'Daily Income Per Truck'!D$1) -> 0 | E3: =SUMIFS(Combined!$O:$O,Combined!$G:$G,'Daily Income Per Truck'!$A3,Combined!$AH:$AH,'Daily Income Per Truck'!E$1) -> 0 | F3: =SUMIFS(Combined!$O:$O,Combined!$G:$G,'Daily Income Per Truck'!$A3,Combined!$AH:$AH,'Daily Income Per Truck'!F$1) -> 0 | G3: =SUMIFS(Combined!$O:$O,Combined!$G:$G,'Daily Income Per Truck'!$A3,Combined!$AH:$AH,'Daily Income Per Truck'!G$1) -> 0 | H3: =SUMIFS(Combined!$O:$O,Combined!$G:$G,'Daily Income Per Truck'!$A3,Combined!$AH:$AH,'Daily Income Per Truck'!H$1) -> 0 | I3: =SUMIFS(Combined!$O:$O,Combined!$G:$G,'Daily Income Per Truck'!$A3,Combined!$AH:$AH,'Daily Income Per Truck'!I$1) -> 0 | ... AF3: =SUMIFS(Combined!$O:$O,Combined!$G:$G,'Daily Income Per Truck'!$A3,Combined!$AH:$AH,'Daily Income Per Truck'!AF$1) -> 0 | AG3: =SUM(B3:AF3) -> 0
A4: =Data!F4 -> KX31ZNGP - FL09 | B4: =SUMIFS(Combined!$O:$O,Combined!$G:$G,'Daily Income Per Truck'!$A4,Combined!$AH:$AH,'Daily Income Per Truck'!B$1) -> 0 | C4: =SUMIFS(Combined!$O:$O,Combined!$G:$G,'Daily Income Per Truck'!$A4,Combined!$AH:$AH,'Daily Income Per Truck'!C$1) -> 0 | D4: =SUMIFS(Combined!$O:$O,Combined!$G:$G,'Daily Income Per Truck'!$A4,Combined!$AH:$AH,'Daily Income Per Truck'!D$1) -> 0 | E4: =SUMIFS(Combined!$O:$O,Combined!$G:$G,'Daily Income Per Truck'!$A4,Combined!$AH:$AH,'Daily Income Per Truck'!E$1) -> 0 | F4: =SUMIFS(Combined!$O:$O,Combined!$G:$G,'Daily Income Per Truck'!$A4,Combined!$AH:$AH,'Daily Income Per Truck'!F$1) -> 0 | G4: =SUMIFS(Combined!$O:$O,Combined!$G:$G,'Daily Income Per Truck'!$A4,Combined!$AH:$AH,'Daily Income Per Truck'!G$1) -> 0 | H4: =SUMIFS(Combined!$O:$O,Combined!$G:$G,'Daily Income Per Truck'!$A4,Combined!$AH:$AH,'Daily Income Per Truck'!H$1) -> 0 | I4: =SUMIFS(Combined!$O:$O,Combined!$G:$G,'Daily Income Per Truck'!$A4,Combined!$AH:$AH,'Daily Income Per Truck'!I$1) -> 0 | ... AF4: =SUMIFS(Combined!$O:$O,Combined!$G:$G,'Daily Income Per Truck'!$A4,Combined!$AH:$AH,'Daily Income Per Truck'!AF$1) -> 0 | AG4: =SUM(B4:AF4) -> 0
A5: =Data!F5 -> KX31ZSGP - FL25 | B5: =SUMIFS(Combined!$O:$O,Combined!$G:$G,'Daily Income Per Truck'!$A5,Combined!$AH:$AH,'Daily Income Per Truck'!B$1) -> 0 | C5: =SUMIFS(Combined!$O:$O,Combined!$G:$G,'Daily Income Per Truck'!$A5,Combined!$AH:$AH,'Daily Income Per Truck'!C$1) -> 0 | D5: =SUMIFS(Combined!$O:$O,Combined!$G:$G,'Daily Income Per Truck'!$A5,Combined!$AH:$AH,'Daily Income Per Truck'!D$1) -> 0 | E5: =SUMIFS(Combined!$O:$O,Combined!$G:$G,'Daily Income Per Truck'!$A5,Combined!$AH:$AH,'Daily Income Per Truck'!E$1) -> 0 | F5: =SUMIFS(Combined!$O:$O,Combined!$G:$G,'Daily Income Per Truck'!$A5,Combined!$AH:$AH,'Daily Income Per Truck'!F$1) -> 0 | G5: =SUMIFS(Combined!$O:$O,Combined!$G:$G,'Daily Income Per Truck'!$A5,Combined!$AH:$AH,'Daily Income Per Truck'!G$1) -> 0 | H5: =SUMIFS(Combined!$O:$O,Combined!$G:$G,'Daily Income Per Truck'!$A5,Combined!$AH:$AH,'Daily Income Per Truck'!H$1) -> 0 | I5: =SUMIFS(Combined!$O:$O,Combined!$G:$G,'Daily Income Per Truck'!$A5,Combined!$AH:$AH,'Daily Income Per Truck'!I$1) -> 0 | ... AF5: =SUMIFS(Combined!$O:$O,Combined!$G:$G,'Daily Income Per Truck'!$A5,Combined!$AH:$AH,'Daily Income Per Truck'!AF$1) -> 0 | AG5: =SUM(B5:AF5) -> 0
A6: =Data!F6 -> KX32BVGP - FL23 | B6: =SUMIFS(Combined!$O:$O,Combined!$G:$G,'Daily Income Per Truck'!$A6,Combined!$AH:$AH,'Daily Income Per Truck'!B$1) -> 0 | C6: =SUMIFS(Combined!$O:$O,Combined!$G:$G,'Daily Income Per Truck'!$A6,Combined!$AH:$AH,'Daily Income Per Truck'!C$1) -> 0 | D6: =SUMIFS(Combined!$O:$O,Combined!$G:$G,'Daily Income Per Truck'!$A6,Combined!$AH:$AH,'Daily Income Per Truck'!D$1) -> 0 | E6: =SUMIFS(Combined!$O:$O,Combined!$G:$G,'Daily Income Per Truck'!$A6,Combined!$AH:$AH,'Daily Income Per Truck'!E$1) -> 0 | F6: =SUMIFS(Combined!$O:$O,Combined!$G:$G,'Daily Income Per Truck'!$A6,Combined!$AH:$AH,'Daily Income Per Truck'!F$1) -> 0 | G6: =SUMIFS(Combined!$O:$O,Combined!$G:$G,'Daily Income Per Truck'!$A6,Combined!$AH:$AH,'Daily Income Per Truck'!G$1) -> 0 | H6: =SUMIFS(Combined!$O:$O,Combined!$G:$G,'Daily Income Per Truck'!$A6,Combined!$AH:$AH,'Daily Income Per Truck'!H$1) -> 0 | I6: =SUMIFS(Combined!$O:$O,Combined!$G:$G,'Daily Income Per Truck'!$A6,Combined!$AH:$AH,'Daily Income Per Truck'!I$1) -> 0 | ... AF6: =SUMIFS(Combined!$O:$O,Combined!$G:$G,'Daily Income Per Truck'!$A6,Combined!$AH:$AH,'Daily Income Per Truck'!AF$1) -> 0 | AG6: =SUM(B6:AF6) -> 0
A7: =Data!F7 -> KX32CMGP - FL10 | B7: =SUMIFS(Combined!$O:$O,Combined!$G:$G,'Daily Income Per Truck'!$A7,Combined!$AH:$AH,'Daily Income Per Truck'!B$1) -> 0 | C7: =SUMIFS(Combined!$O:$O,Combined!$G:$G,'Daily Income Per Truck'!$A7,Combined!$AH:$AH,'Daily Income Per Truck'!C$1) -> 0 | D7: =SUMIFS(Combined!$O:$O,Combined!$G:$G,'Daily Income Per Truck'!$A7,Combined!$AH:$AH,'Daily Income Per Truck'!D$1) -> 0 | E7: =SUMIFS(Combined!$O:$O,Combined!$G:$G,'Daily Income Per Truck'!$A7,Combined!$AH:$AH,'Daily Income Per Truck'!E$1) -> 0 | F7: =SUMIFS(Combined!$O:$O,Combined!$G:$G,'Daily Income Per Truck'!$A7,Combined!$AH:$AH,'Daily Income Per Truck'!F$1) -> 0 | G7: =SUMIFS(Combined!$O:$O,Combined!$G:$G,'Daily Income Per Truck'!$A7,Combined!$AH:$AH,'Daily Income Per Truck'!G$1) -> 0 | H7: =SUMIFS(Combined!$O:$O,Combined!$G:$G,'Daily Income Per Truck'!$A7,Combined!$AH:$AH,'Daily Income Per Truck'!H$1) -> 0 | I7: =SUMIFS(Combined!$O:$O,Combined!$G:$G,'Daily Income Per Truck'!$A7,Combined!$AH:$AH,'Daily Income Per Truck'!I$1) -> 0 | ... AF7: =SUMIFS(Combined!$O:$O,Combined!$G:$G,'Daily Income Per Truck'!$A7,Combined!$AH:$AH,'Daily Income Per Truck'!AF$1) -> 0 | AG7: =SUM(B7:AF7) -> 0
A8: =Data!F8 -> KX32CXGP - FL14 | B8: =SUMIFS(Combined!$O:$O,Combined!$G:$G,'Daily Income Per Truck'!$A8,Combined!$AH:$AH,'Daily Income Per Truck'!B$1) -> 0 | C8: =SUMIFS(Combined!$O:$O,Combined!$G:$G,'Daily Income Per Truck'!$A8,Combined!$AH:$AH,'Daily Income Per Truck'!C$1) -> 0 | D8: =SUMIFS(Combined!$O:$O,Combined!$G:$G,'Daily Income Per Truck'!$A8,Combined!$AH:$AH,'Daily Income Per Truck'!D$1) -> 0 | E8: =SUMIFS(Combined!$O:$O,Combined!$G:$G,'Daily Income Per Truck'!$A8,Combined!$AH:$AH,'Daily Income Per Truck'!E$1) -> 0 | F8: =SUMIFS(Combined!$O:$O,Combined!$G:$G,'Daily Income Per Truck'!$A8,Combined!$AH:$AH,'Daily Income Per Truck'!F$1) -> 0 | G8: =SUMIFS(Combined!$O:$O,Combined!$G:$G,'Daily Income Per Truck'!$A8,Combined!$AH:$AH,'Daily Income Per Truck'!G$1) -> 0 | H8: =SUMIFS(Combined!$O:$O,Combined!$G:$G,'Daily Income Per Truck'!$A8,Combined!$AH:$AH,'Daily Income Per Truck'!H$1) -> 0 | I8: =SUMIFS(Combined!$O:$O,Combined!$G:$G,'Daily Income Per Truck'!$A8,Combined!$AH:$AH,'Daily Income Per Truck'!I$1) -> 0 | ... AF8: =SUMIFS(Combined!$O:$O,Combined!$G:$G,'Daily Income Per Truck'!$A8,Combined!$AH:$AH,'Daily Income Per Truck'!AF$1) -> 0 | AG8: =SUM(B8:AF8) -> 0
A9: =Data!F9 -> KX32DBGP - FL12 | B9: =SUMIFS(Combined!$O:$O,Combined!$G:$G,'Daily Income Per Truck'!$A9,Combined!$AH:$AH,'Daily Income Per Truck'!B$1) -> 0 | C9: =SUMIFS(Combined!$O:$O,Combined!$G:$G,'Daily Income Per Truck'!$A9,Combined!$AH:$AH,'Daily Income Per Truck'!C$1) -> 0 | D9: =SUMIFS(Combined!$O:$O,Combined!$G:$G,'Daily Income Per Truck'!$A9,Combined!$AH:$AH,'Daily Income Per Truck'!D$1) -> 0 | E9: =SUMIFS(Combined!$O:$O,Combined!$G:$G,'Daily Income Per Truck'!$A9,Combined!$AH:$AH,'Daily Income Per Truck'!E$1) -> 0 | F9: =SUMIFS(Combined!$O:$O,Combined!$G:$G,'Daily Income Per Truck'!$A9,Combined!$AH:$AH,'Daily Income Per Truck'!F$1) -> 0 | G9: =SUMIFS(Combined!$O:$O,Combined!$G:$G,'Daily Income Per Truck'!$A9,Combined!$AH:$AH,'Daily Income Per Truck'!G$1) -> 0 | H9: =SUMIFS(Combined!$O:$O,Combined!$G:$G,'Daily Income Per Truck'!$A9,Combined!$AH:$AH,'Daily Income Per Truck'!H$1) -> 0 | I9: =SUMIFS(Combined!$O:$O,Combined!$G:$G,'Daily Income Per Truck'!$A9,Combined!$AH:$AH,'Daily Income Per Truck'!I$1) -> 0 | ... AF9: =SUMIFS(Combined!$O:$O,Combined!$G:$G,'Daily Income Per Truck'!$A9,Combined!$AH:$AH,'Daily Income Per Truck'!AF$1) -> 0 | AG9: =SUM(B9:AF9) -> 0
A10: =Data!F10 -> LC18JZGP - FL29 | B10: =SUMIFS(Combined!$O:$O,Combined!$G:$G,'Daily Income Per Truck'!$A10,Combined!$AH:$AH,'Daily Income Per Truck'!B$1) -> 0 | C10: =SUMIFS(Combined!$O:$O,Combined!$G:$G,'Daily Income Per Truck'!$A10,Combined!$AH:$AH,'Daily Income Per Truck'!C$1) -> 0 | D10: =SUMIFS(Combined!$O:$O,Combined!$G:$G,'Daily Income Per Truck'!$A10,Combined!$AH:$AH,'Daily Income Per Truck'!D$1) -> 0 | E10: =SUMIFS(Combined!$O:$O,Combined!$G:$G,'Daily Income Per Truck'!$A10,Combined!$AH:$AH,'Daily Income Per Truck'!E$1) -> 0 | F10: =SUMIFS(Combined!$O:$O,Combined!$G:$G,'Daily Income Per Truck'!$A10,Combined!$AH:$AH,'Daily Income Per Truck'!F$1) -> 0 | G10: =SUMIFS(Combined!$O:$O,Combined!$G:$G,'Daily Income Per Truck'!$A10,Combined!$AH:$AH,'Daily Income Per Truck'!G$1) -> 0 | H10: =SUMIFS(Combined!$O:$O,Combined!$G:$G,'Daily Income Per Truck'!$A10,Combined!$AH:$AH,'Daily Income Per Truck'!H$1) -> 0 | I10: =SUMIFS(Combined!$O:$O,Combined!$G:$G,'Daily Income Per Truck'!$A10,Combined!$AH:$AH,'Daily Income Per Truck'!I$1) -> 0 | ... AF10: =SUMIFS(Combined!$O:$O,Combined!$G:$G,'Daily Income Per Truck'!$A10,Combined!$AH:$AH,'Daily Income Per Truck'!AF$1) -> 0 | AG10: =SUM(B10:AF10) -> 0
A11: =Data!F11 -> LC18KGGP - FL27 | B11: =SUMIFS(Combined!$O:$O,Combined!$G:$G,'Daily Income Per Truck'!$A11,Combined!$AH:$AH,'Daily Income Per Truck'!B$1) -> 0 | C11: =SUMIFS(Combined!$O:$O,Combined!$G:$G,'Daily Income Per Truck'!$A11,Combined!$AH:$AH,'Daily Income Per Truck'!C$1) -> 0 | D11: =SUMIFS(Combined!$O:$O,Combined!$G:$G,'Daily Income Per Truck'!$A11,Combined!$AH:$AH,'Daily Income Per Truck'!D$1) -> 0 | E11: =SUMIFS(Combined!$O:$O,Combined!$G:$G,'Daily Income Per Truck'!$A11,Combined!$AH:$AH,'Daily Income Per Truck'!E$1) -> 0 | F11: =SUMIFS(Combined!$O:$O,Combined!$G:$G,'Daily Income Per Truck'!$A11,Combined!$AH:$AH,'Daily Income Per Truck'!F$1) -> 0 | G11: =SUMIFS(Combined!$O:$O,Combined!$G:$G,'Daily Income Per Truck'!$A11,Combined!$AH:$AH,'Daily Income Per Truck'!G$1) -> 0 | H11: =SUMIFS(Combined!$O:$O,Combined!$G:$G,'Daily Income Per Truck'!$A11,Combined!$AH:$AH,'Daily Income Per Truck'!H$1) -> 0 | I11: =SUMIFS(Combined!$O:$O,Combined!$G:$G,'Daily Income Per Truck'!$A11,Combined!$AH:$AH,'Daily Income Per Truck'!I$1) -> 0 | ... AF11: =SUMIFS(Combined!$O:$O,Combined!$G:$G,'Daily Income Per Truck'!$A11,Combined!$AH:$AH,'Daily Income Per Truck'!AF$1) -> 0 | AG11: =SUM(B11:AF11) -> 0
A12: =Data!F12 -> LC18KPGP - FL05 | B12: =SUMIFS(Combined!$O:$O,Combined!$G:$G,'Daily Income Per Truck'!$A12,Combined!$AH:$AH,'Daily Income Per Truck'!B$1) -> 0 | C12: =SUMIFS(Combined!$O:$O,Combined!$G:$G,'Daily Income Per Truck'!$A12,Combined!$AH:$AH,'Daily Income Per Truck'!C$1) -> 0 | D12: =SUMIFS(Combined!$O:$O,Combined!$G:$G,'Daily Income Per Truck'!$A12,Combined!$AH:$AH,'Daily Income Per Truck'!D$1) -> 0 | E12: =SUMIFS(Combined!$O:$O,Combined!$G:$G,'Daily Income Per Truck'!$A12,Combined!$AH:$AH,'Daily Income Per Truck'!E$1) -> 0 | F12: =SUMIFS(Combined!$O:$O,Combined!$G:$G,'Daily Income Per Truck'!$A12,Combined!$AH:$AH,'Daily Income Per Truck'!F$1) -> 0 | G12: =SUMIFS(Combined!$O:$O,Combined!$G:$G,'Daily Income Per Truck'!$A12,Combined!$AH:$AH,'Daily Income Per Truck'!G$1) -> 12322.086 | H12: =SUMIFS(Combined!$O:$O,Combined!$G:$G,'Daily Income Per Truck'!$A12,Combined!$AH:$AH,'Daily Income Per Truck'!H$1) -> 12422.049 | I12: =SUMIFS(Combined!$O:$O,Combined!$G:$G,'Daily Income Per Truck'!$A12,Combined!$AH:$AH,'Daily Income Per Truck'!I$1) -> 5048.1683 | ... AF12: =SUMIFS(Combined!$O:$O,Combined!$G:$G,'Daily Income Per Truck'!$A12,Combined!$AH:$AH,'Daily Income Per Truck'!AF$1) -> 0 | AG12: =SUM(B12:AF12) -> 29792.303
A13: =Data!F13 -> LC18KWGP - FL06 | B13: =SUMIFS(Combined!$O:$O,Combined!$G:$G,'Daily Income Per Truck'!$A13,Combined!$AH:$AH,'Daily Income Per Truck'!B$1) -> 0 | C13: =SUMIFS(Combined!$O:$O,Combined!$G:$G,'Daily Income Per Truck'!$A13,Combined!$AH:$AH,'Daily Income Per Truck'!C$1) -> 0 | D13: =SUMIFS(Combined!$O:$O,Combined!$G:$G,'Daily Income Per Truck'!$A13,Combined!$AH:$AH,'Daily Income Per Truck'!D$1) -> 0 | E13: =SUMIFS(Combined!$O:$O,Combined!$G:$G,'Daily Income Per Truck'!$A13,Combined!$AH:$AH,'Daily Income Per Truck'!E$1) -> 0 | F13: =SUMIFS(Combined!$O:$O,Combined!$G:$G,'Daily Income Per Truck'!$A13,Combined!$AH:$AH,'Daily Income Per Truck'!F$1) -> 0 | G13: =SUMIFS(Combined!$O:$O,Combined!$G:$G,'Daily Income Per Truck'!$A13,Combined!$AH:$AH,'Daily Income Per Truck'!G$1) -> 0 | H13: =SUMIFS(Combined!$O:$O,Combined!$G:$G,'Daily Income Per Truck'!$A13,Combined!$AH:$AH,'Daily Income Per Truck'!H$1) -> 0 | I13: =SUMIFS(Combined!$O:$O,Combined!$G:$G,'Daily Income Per Truck'!$A13,Combined!$AH:$AH,'Daily Income Per Truck'!I$1) -> 0 | ... AF13: =SUMIFS(Combined!$O:$O,Combined!$G:$G,'Daily Income Per Truck'!$A13,Combined!$AH:$AH,'Daily Income Per Truck'!AF$1) -> 0 | AG13: =SUM(B13:AF13) -> 0
... A200: =Data!F200 -> 0 | B200: =SUMIFS(Combined!$O:$O,Combined!$G:$G,'Daily Income Per Truck'!$A200,Combined!$AH:$AH,'Daily Income Per Truck'!B$1) -> 0 | C200: =SUMIFS(Combined!$O:$O,Combined!$G:$G,'Daily Income Per Truck'!$A200,Combined!$AH:$AH,'Daily Income Per Truck'!C$1) -> 0 | D200: =SUMIFS(Combined!$O:$O,Combined!$G:$G,'Daily Income Per Truck'!$A200,Combined!$AH:$AH,'Daily Income Per Truck'!D$1) -> 0 | E200: =SUMIFS(Combined!$O:$O,Combined!$G:$G,'Daily Income Per Truck'!$A200,Combined!$AH:$AH,'Daily Income Per Truck'!E$1) -> 0 | F200: =SUMIFS(Combined!$O:$O,Combined!$G:$G,'Daily Income Per Truck'!$A200,Combined!$AH:$AH,'Daily Income Per Truck'!F$1) -> 0 | G200: =SUMIFS(Combined!$O:$O,Combined!$G:$G,'Daily Income Per Truck'!$A200,Combined!$AH:$AH,'Daily Income Per Truck'!G$1) -> 0 | H200: =SUMIFS(Combined!$O:$O,Combined!$G:$G,'Daily Income Per Truck'!$A200,Combined!$AH:$AH,'Daily Income Per Truck'!H$1) -> 0 | I200: =SUMIFS(Combined!$O:$O,Combined!$G:$G,'Daily Income Per Truck'!$A200,Combined!$AH:$AH,'Daily Income Per Truck'!I$1) -> 0 | ... AF200: =SUMIFS(Combined!$O:$O,Combined!$G:$G,'Daily Income Per Truck'!$A200,Combined!$AH:$AH,'Daily Income Per Truck'!AF$1) -> 0 | AG200: =SUM(B200:AF200) -> 0
A201: Daily Total | B201: =SUM(B2:B200) -> 4994.7932 | C201: =SUM(C2:C200) -> 0 | D201: =SUM(D2:D200) -> 0 | E201: =SUM(E2:E200) -> 0 | F201: =SUM(F2:F200) -> 5345.9457 | G201: =SUM(G2:G200) -> 24925.016 | H201: =SUM(H2:H200) -> 28181.773 | I201: =SUM(I2:I200) -> 5048.1683 | ... AF201: =SUM(AF2:AF200) -> 0
AD203: Monthly Total | AG203: =SUM(AG2:AG202) -> 68495.697

Sheet Data
A1: Route | B1: Distance (Km) | C1: Rate | D1: Month | E1: Company | F1: Reg # | G1: Driver Name | I1: Normal Rate Per Kilometer | J1: Sunday &Holiday Rate
A2: Exxaro Leeuwpan - Sasol Bosjesspruit | B2: 102 | C2: 129.72 | D2: Jan | E2: Fleet Logix | F2: KX31ZJGP - FL13 | G2: Ayanda Tembe | I2: 3.5 | J2: 5
A3: Exxaro Leeuwpan - Sasol Site 1 | B3: 85 | C3: 115.09 | D3: Feb | F3: KX31ZLGP - FL04 | G3: Meshack Khathide
A4: Exxaro Leeuwpan - Sasol Site 1 | B4: 85 | C4: 115.09 | D4: Mar | F4: KX31ZNGP - FL09 | G4: Sihle Thabo Nkosi
A5: Kleinfontein - Arnot | B5: 145 | C5: 230 | D5: Apr | F5: KX31ZSGP - FL25 | G5: Sandile Peter Nzimande
A6: Leeuwport Mine - Lk Tlou | B6: 29 | C6: 40 | D6: May | F6: KX32BVGP - FL23 | G6: Witness Nkosi
A7: Lk Tlou - Middelbult | B7: 70 | C7: 106.98 | D7: Jun | F7: KX32CMGP - FL10 | G7: Themba Simelane
A8: Lk Tlou - Sasol Bosjesspruit | B8: 85 | C8: 126.79 | D8: Jul | F8: KX32CXGP - FL14 | G8: Welcome Mashaya
A9: Lk Tlou - Sasol Impumelelo | B9: 73 | C9: 111.12 | D9: Aug | F9: KX32DBGP - FL12 | G9: Production Mthethwa
A10: Lk Tlou - Shondoni | B10: 58 | C10: 100.98 | D10: Sept | F10: LC18JZGP - FL29 | G10: Bhekinkozi Ismael Zwane
A11: Lk Tlou - Site -1,2.,3,4& Matla Pad | B11: 75 | C11: 122.14 | D11: Oct | F11: LC18KGGP - FL27 | G11: Siphesihle Xaba
A12: LK Tlou - Arnot | B12: 145 | C12: 230 | D12: Nov | F12: LC18KPGP - FL05 | G12: Albert Mduduzi Zikalala
A13: LK Tlou - Kleinfontein | B13: 110 | C13: 135 | D13: Dec | F13: LC18KWGP - FL06 | G13: Sandiso Siyaya
A14: LK Tlou - Hendrina | B14: 136 | C14: 210 | F14: LC18KZGP - FL17 | G14: Nkosenhle Ndlovu
A15: Matsambisa Kriel - Arnot | B15: 126 | C15: 147.09 | F15: LC18LFGP - FL08 | G15: Lennox Banele Ncanazo
A16: Matsambisa Kriel - Hendrina Power | B16: 122 | C16: 146.09 | F16: LC18LKGP - FL02 | G16: Sammy Mahlangu
A17: Matsambisa Kriel - Resinga | B17: 96 | C17: 120 | F17: LC18LTGP - FL30 | G17: Xolani Ngcobo
A18: Mavungwani - Areshumeng | B18: 11 | C18: 28 | F18: LG23HJGP - FL19 | G18: Melizwe Siyaya
A19: Mavungwani - Duvha Power Station | B19: 82 | C19: 123.5 | F19: LG23HTGP - FL15 | G19: Nkosivumile Luphuzi
A20: Mavungwani - Hendrina Power | B20: 47 | C20: 82.5 | F20: LG23KSGP - FL28 | G20: Dumusani Masilela
A21: Mavungwani - Matla Power | B21: 108 | C21: 157.7 | F21: LG23MCGP - FL26 | G21: Khanyisani Lembethe
A22: Mavungwani - Anthra | B22: 54 | C22: 88 | F22: LG24BKGP - FL24 | G22: Vincent Nkosi
A23: Mavungwani - Witrand | B23: 31 | C23: 40 | F23: LG24BXGP - FL16 | G23: Mlungisi Nkambula
A24: Mwalimu - Umlabu | B24: 41 | C24: 62 | F24: LG24CDGP - FL22 | G24: Zamani Buthelezi
A25: Resinga Mine - Arnot | B25: 52 | C25: 78 | F25: LG24CKGP - FL21 | G25: Wonder Innocent Kubheka
... A40: Mooiplaats- Mmc | B40: 71 | C40: 106 | F40: LD93XWGP-FL41 | G40: Nhlanhla Mafutha Myeni
A41: Blesbok-Wakefield | B41: 64 | C41: 89 | G41: Nhlanhla Mamba
A42: Frontier-Forzando | B42: 87 | C42: 98 | G42: Wonderful Sandile Qwabe
A43: Kleinfontein - Tlou Kanglala Plant | B43: 120 | C43: 169 | G43: Mehluko Ntsele
A44: Bankfontein-Frontier | B44: 91 | C44: 143 | G44: Sibusiso Nthangase
A45: Tlou -Kangala | B45: 23 | C45: 52 | G45: Menzi Hatshwayo
A46: Wakefield-Frontier | B46: 70 | C46: 111.8 | G46: Bheki Zulu
A47: MMC -Dorsfontein East | B47: 47 | C47: 58 | G47: Sibusiso Alfred Twala
A48: Kangala-Grootvlei | B48: 89 | C48: 132.5 | G48: Siswe Zwane
G49: Nkululeko Qwabe
G50: Sakhile Freedom Mabaso
G51: Thulani Sabelo Simelane
G52: Nkosiyazi Sibiya
G53: Mbongiseni Mphikeleli Sithole
G54: Msimanga Samson Gift
...

Sheet Costing
A1: LOADING POINT | B1: DESTINATION | C1: DISTANCE | D1: NEW NORMAL RATE PER KILOMETER | E1: NEW AMOUNT | F1: NEW SUNDAY &HOLIDAY RATE | G1: NEW AMOUNT
A2: EXXARO LEEUWPAN | B2: SASOL BOSJESSPRUIT | C2: 102 | D2: 3.3 | E2: =C2*D2 -> 336.6 | F2: 4.8 | G2: =C2*F2 -> 489.6
A3: MBALI COLLIERY | B3: SASOL BOSJESSPRUIT | C3: 89 | D3: 3.3 | E3: =C3*D3 -> 293.7 | F3: 4.8 | G3: =C3*F3 -> 427.2
A4: MBALI COLLIERY | B4: SASOL IMPUMELELO | C4: 88 | D4: 3.3 | E4: =C4*D4 -> 290.4 | F4: 4.8 | G4: =C4*F4 -> 422.4
A5: EXXARO LEEUWPAN | B5: SASOL SITE 1 | C5: 85 | D5: 3.3 | E5: =C5*D5 -> 280.5 | F5: 4.8 | G5: =C5*F5 -> 408
A6: MBALI COLLIERY | B6: SASOL SHONDONI | C6: 61 | D6: 3.3 | E6: =C6*D6 -> 201.3 | F6: 4.8 | G6: =C6*F6 -> 292.8
A7: MBALI COLLIERY | B7: SASOL SITE 1 | C7: 66 | D7: 3.3 | E7: =C7*D7 -> 217.8 | F7: 4.8 | G7: =C7*F7 -> 316.8
A8: MBALI COLLIERY | B8: SASOL MIDDELBULT | C8: 66 | D8: 3.3 | E8: =C8*D8 -> 217.8 | F8: 4.8 | G8: =C8*F8 -> 316.8
A9: MAVUNGWANI | B9: MATLA POWER | C9: 108 | D9: 3.3 | E9: =C9*D9 -> 356.4 | F9: 4.8 | G9: =C9*F9 -> 518.4
A10: MAVUNGWANI | B10: DUVHA POWER STATION | C10: 82 | D10: 3.3 | E10: =C10*D10 -> 270.6 | F10: 4.8 | G10: =C10*F10 -> 393.6
A11: MAVUNGWANI | B11: HENDRINA POWER | C11: 47 | D11: 3.3 | E11: =C11*D11 -> 155.1 | F11: 4.8 | G11: =C11*F11 -> 225.6
A12: MAVUNGWANI | B12: ANTHRA | C12: 54 | D12: 3.3 | E12: =C12*D12 -> 178.2 | F12: 4.8 | G12: =C12*F12 -> 259.2
A13: MAVUNGWANI | B13: WITRAND | C13: 31 | D13: 3.3 | E13: =C13*D13 -> 102.3 | F13: 4.8 | G13: =C13*F13 -> 148.8
... A28: LK TLOU | B28: SITE-1,2,3,4& MATLA PAD | C28: 75 | D28: 3.3 | E28: =C28*D28 -> 247.5 | F28: 4.8 | G28: =C28*F28 -> 360
